Workbook
Name AOV: Analysis!$D$22
Name quantity: Analysis!$B$22
Name revenue: Analysis!$A$22

Sheet Dataset
A1: OrderID | B1: Date | C1: CustomerID | D1: Product | E1: Quantity | F1: UnitPrice | G1: ShippingAddress | H1: PaymentMethod | I1: OrderStatus | J1: TrackingNumber | K1: ItemsInCart | L1: CouponCode | M1: ReferralSource | N1: TotalPrice
A2: ORD200000 | B2: 44930 | C2: C72649 | D2: Monitor | E2: 5 | F2: 570.62 | G2: 928 Main St | H2: Debit Card | I2: Shipped | J2: TRK37947903 | K2: 7 | L2: SAVE10 | M2: Instagram | N2: 2853.1
A3: ORD200001 | B3: 45527 | C3: C75739 | D3: Phone | E3: 2 | F3: 151.35 | G3: 823 Main St | H3: Online | I3: Shipped | J3: TRK91186779 | K3: 3 | L3: SAVE10 | M3: Referral | N3: 302.7
A4: ORD200002 | B4: 45349 | C4: C81728 | D4: Tablet | E4: 5 | F4: 550.68 | G4: 512 Main St | H4: Credit Card | I4: Cancelled | J4: TRK42903982 | K4: 8 | L4: FREESHIP | M4: Email | N4: 2753.4
A5: ORD200003 | B5: 45214 | C5: C33540 | D5: Chair | E5: 1 | F5: 273.19 | G5: 275 Main St | H5: Debit Card | I5: Returned | J5: TRK62788070 | K5: 5 | L5: SAVE10 | M5: Facebook | N5: 273.19
A6: ORD200004 | B6: 45785 | C6: C81840 | D6: Printer | E6: 4 | F6: 626.01 | G6: 668 Main St | H6: Online | I6: Delivered | J6: TRK29241424 | K6: 8 | L6: SAVE10 | M6: Email | N6: 2504.04
A7: ORD200005 | B7: 45222 | C7: C37249 | D7: Phone | E7: 2 | F7: 245.86 | G7: 934 Main St | H7: Credit Card | I7: Shipped | J7: TRK72976927 | K7: 4 | L7: SAVE10 | M7: Instagram | N7: 491.72
A8: ORD200006 | B8: 45825 | C8: C83492 | D8: Laptop | E8: 1 | F8: 664.42 | G8: 986 Main St | H8: Gift Card | I8: Returned | J8: TRK96417362 | K8: 6 | L8: SAVE10 | M8: Facebook | N8: 664.42
A9: ORD200007 | B9: 45058 | C9: C41460 | D9: Monitor | E9: 5 | F9: 149.55 | G9: 706 Main St | H9: Cash | I9: Shipped | J9: TRK78809193 | K9: 9 | L9: FREESHIP | M9: Facebook | N9: 747.75
A10: ORD200008 | B10: 45749 | C10: C26817 | D10: Phone | E10: 2 | F10: 134.28 | G10: 904 Main St | H10: Gift Card | I10: Cancelled | J10: TRK61042692 | K10: 2 | M10: Email | N10: 268.56
A11: ORD200009 | B11: 45251 | C11: C31946 | D11: Desk | E11: 4 | F11: 509.38 | G11: 102 Main St | H11: Credit Card | I11: Shipped | J11: TRK33478363 | K11: 6 | L11: SAVE10 | M11: Google | N11: 2037.52
A12: ORD200010 | B12: 45289 | C12: C43443 | D12: Tablet | E12: 5 | F12: 625.97 | G12: 333 Main St | H12: Credit Card | I12: Returned | J12: TRK98859248 | K12: 9 | L12: WINTER15 | M12: Instagram | N12: 3129.85
A13: ORD200011 | B13: 45339 | C13: C93861 | D13: Monitor | E13: 3 | F13: 49.14 | G13: 831 Main St | H13: Online | I13: Returned | J13: TRK48234646 | K13: 7 | L13: SAVE10 | M13: Email | N13: 147.42
A14: ORD200012 | B14: 45580 | C14: C38785 | D14: Monitor | E14: 2 | F14: 180.5 | G14: 179 Main St | H14: Debit Card | I14: Pending | J14: TRK20419991 | K14: 6 | L14: FREESHIP | M14: Referral | N14: 361
A15: ORD200013 | B15: 45168 | C15: C88348 | D15: Laptop | E15: 3 | F15: 201.49 | G15: 903 Main St | H15: Credit Card | I15: Returned | J15: TRK81913874 | K15: 4 | L15: FREESHIP | M15: Facebook | N15: 604.47
A16: ORD200014 | B16: 45012 | C16: C98474 | D16: Tablet | E16: 2 | F16: 393.33 | G16: 980 Main St | H16: Debit Card | I16: Pending | J16: TRK79186539 | K16: 3 | L16: SAVE10 | M16: Instagram | N16: 786.66
A17: ORD200015 | B17: 45124 | C17: C39416 | D17: Printer | E17: 1 | F17: 473.96 | G17: 942 Main St | H17: Cash | I17: Delivered | J17: TRK54930938 | K17: 3 | M17: Google | N17: 473.96
A18: ORD200016 | B18: 44950 | C18: C28976 | D18: Printer | E18: 2 | F18: 533.81 | G18: 914 Main St | H18: Credit Card | I18: Pending | J18: TRK13194259 | K18: 3 | L18: FREESHIP | M18: Email | N18: 1067.62
A19: ORD200017 | B19: 45353 | C19: C60672 | D19: Tablet | E19: 1 | F19: 423.4 | G19: 382 Main St | H19: Debit Card | I19: Shipped | J19: TRK11972116 | K19: 3 | M19: Referral | N19: 423.4
A20: ORD200018 | B20: 45742 | C20: C84329 | D20: Desk | E20: 1 | F20: 431.44 | G20: 891 Main St | H20: Gift Card | I20: Pending | J20: TRK65191045 | K20: 3 | L20: SAVE10 | M20: Facebook | N20: 431.44
A21: ORD200019 | B21: 44949 | C21: C14552 | D21: Monitor | E21: 5 | F21: 224 | G21: 273 Main St | H21: Cash | I21: Returned | J21: TRK59101365 | K21: 9 | L21: SAVE10 | M21: Google | N21: 1120
A22: ORD200020 | B22: 45054 | C22: C54829 | D22: Chair | E22: 5 | F22: 62.51 | G22: 587 Main St | H22: Cash | I22: Pending | J22: TRK16718651 | K22: 9 | L22: WINTER15 | M22: Instagram | N22: 312.55
A23: ORD200021 | B23: 45613 | C23: C99023 | D23: Monitor | E23: 4 | F23: 342.95 | G23: 569 Main St | H23: Cash | I23: Delivered | J23: TRK52646983 | K23: 6 | M23: Google | N23: 1371.8
A24: ORD200022 | B24: 44955 | C24: C34416 | D24: Monitor | E24: 2 | F24: 49.62 | G24: 633 Main St | H24: Online | I24: Pending | J24: TRK75937350 | K24: 2 | L24: SAVE10 | M24: Google | N24: 99.24
A25: ORD200023 | B25: 45756 | C25: C42372 | D25: Phone | E25: 4 | F25: 273.25 | G25: 755 Main St | H25: Debit Card | I25: Cancelled | J25: TRK36168083 | K25: 5 | L25: FREESHIP | M25: Referral | N25: 1093
A26: ORD200024 | B26: 45595 | C26: C17470 | D26: Laptop | E26: 2 | F26: 230.95 | G26: 956 Main St | H26: Online | I26: Delivered | J26: TRK28775057 | K26: 3 | L26: WINTER15 | M26: Referral | N26: 461.9
A27: ORD200025 | B27: 45497 | C27: C42577 | D27: Monitor | E27: 1 | F27: 399.98 | G27: 709 Main St | H27: Debit Card | I27: Delivered | J27: TRK69423327 | K27: 3 | L27: WINTER15 | M27: Email | N27: 399.98
A28: ORD200026 | B28: 45357 | C28: C21944 | D28: Laptop | E28: 5 | F28: 59.55 | G28: 296 Main St | H28: Online | I28: Delivered | J28: TRK80276812 | K28: 6 | M28: Referral | N28: 297.75
A29: ORD200027 | B29: 45344 | C29: C97593 | D29: Printer | E29: 1 | F29: 472.74 | G29: 881 Main St | H29: Online | I29: Shipped | J29: TRK89117573 | K29: 6 | L29: WINTER15 | M29: Google | N29: 472.74
A30: ORD200028 | B30: 45251 | C30: C59823 | D30: Phone | E30: 4 | F30: 160.07 | G30: 568 Main St | H30: Online | I30: Pending | J30: TRK65895539 | K30: 5 | M30: Email | N30: 640.28
A31: ORD200029 | B31: 45555 | C31: C33260 | D31: Desk | E31: 3 | F31: 423.53 | G31: 930 Main St | H31: Credit Card | I31: Delivered | J31: TRK59744090 | K31: 6 | L31: SAVE10 | M31: Referral | N31: 1270.59
A32: ORD200030 | B32: 45738 | C32: C44267 | D32: Monitor | E32: 2 | F32: 426.7 | G32: 895 Main St | H32: Online | I32: Pending | J32: TRK54751444 | K32: 5 | L32: SAVE10 | M32: Referral | N32: 853.4
A33: ORD200031 | B33: 45107 | C33: C26445 | D33: Chair | E33: 3 | F33: 500.08 | G33: 996 Main St | H33: Debit Card | I33: Returned | J33: TRK31229981 | K33: 6 | M33: Facebook | N33: 1500.24
A34: ORD200032 | B34: 45047 | C34: C12388 | D34: Tablet | E34: 5 | F34: 536.72 | G34: 830 Main St | H34: Cash | I34: Delivered | J34: TRK99261395 | K34: 10 | M34: Email | N34: 2683.6
A35: ORD200033 | B35: 45082 | C35: C52184 | D35: Chair | E35: 1 | F35: 162.77 | G35: 912 Main St | H35: Online | I35: Cancelled | J35: TRK73312471 | K35: 4 | L35: WINTER15 | M35: Facebook | N35: 162.77
A36: ORD200034 | B36: 44933 | C36: C67195 | D36: Chair | E36: 4 | F36: 576.52 | G36: 926 Main St | H36: Credit Card | I36: Pending | J36: TRK55467915 | K36: 5 | L36: WINTER15 | M36: Facebook | N36: 2306.08
A37: ORD200035 | B37: 45633 | C37: C50304 | D37: Monitor | E37: 2 | F37: 465.15 | G37: 128 Main St | H37: Online | I37: Shipped | J37: TRK46850888 | K37: 2 | L37: SAVE10 | M37: Facebook | N37: 930.3
A38: ORD200036 | B38: 45785 | C38: C59337 | D38: Laptop | E38: 2 | F38: 534.43 | G38: 465 Main St | H38: Debit Card | I38: Pending | J38: TRK50961250 | K38: 5 | M38: Facebook | N38: 1068.86
A39: ORD200037 | B39: 45579 | C39: C10054 | D39: Laptop | E39: 2 | F39: 76.74 | G39: 409 Main St | H39: Cash | I39: Returned | J39: TRK94005261 | K39: 7 | L39: SAVE10 | M39: Instagram | N39: 153.48
A40: ORD200038 | B40: 45645 | C40: C15924 | D40: Laptop | E40: 1 | F40: 245.89 | G40: 549 Main St | H40: Debit Card | I40: Delivered | J40: TRK14835975 | K40: 3 | L40: SAVE10 | M40: Google | N40: 245.89
...

Sheet clean_data
A1: OrderID | B1: Date | C1: CustomerID | D1: Product | E1: Quantity | F1: UnitPrice | G1: ShippingAddress | H1: PaymentMethod | I1: OrderStatus | J1: TrackingNumber | K1: ItemsInCart | L1: CouponCode | M1: ReferralSource | N1: TotalPrice
A2: =TRIM(Dataset!A2) -> ORD200000 | B2: =Dataset!B2 -> 44930 | C2: =TRIM(Dataset!C2) -> C72649 | D2: =TRIM(Dataset!D2) -> Monitor | E2: =VALUE(TRIM(Dataset!E2)) -> 5 | F2: =VALUE(TRIM(Dataset!F2)) -> 570.62 | G2: =TRIM(Dataset!G2) -> 928 Main St | H2: =TRIM(Dataset!H2) -> Debit Card | I2: =TRIM(Dataset!I2) -> Shipped | J2: =TRIM(Dataset!J2) -> TRK37947903 | K2: =TRIM(Dataset!K2) -> 7 | L2: =Dataset!L2 -> SAVE10 | M2: =TRIM(Dataset!M2) -> Instagram | N2: =VALUE(TRIM(Dataset!N2)) -> 2853.1
A3: =TRIM(Dataset!A3) -> ORD200001 | B3: =Dataset!B3 -> 45527 | C3: =TRIM(Dataset!C3) -> C75739 | D3: =TRIM(Dataset!D3) -> Phone | E3: =VALUE(TRIM(Dataset!E3)) -> 2 | F3: =VALUE(TRIM(Dataset!F3)) -> 151.35 | G3: =TRIM(Dataset!G3) -> 823 Main St | H3: =TRIM(Dataset!H3) -> Online | I3: =TRIM(Dataset!I3) -> Shipped | J3: =TRIM(Dataset!J3) -> TRK91186779 | K3: =TRIM(Dataset!K3) -> 3 | L3: =Dataset!L3 -> SAVE10 | M3: =TRIM(Dataset!M3) -> Referral | N3: =VALUE(TRIM(Dataset!N3)) -> 302.7
A4: =TRIM(Dataset!A4) -> ORD200002 | B4: =Dataset!B4 -> 45349 | C4: =TRIM(Dataset!C4) -> C81728 | D4: =TRIM(Dataset!D4) -> Tablet | E4: =VALUE(TRIM(Dataset!E4)) -> 5 | F4: =VALUE(TRIM(Dataset!F4)) -> 550.68 | G4: =TRIM(Dataset!G4) -> 512 Main St | H4: =TRIM(Dataset!H4) -> Credit Card | I4: =TRIM(Dataset!I4) -> Cancelled | J4: =TRIM(Dataset!J4) -> TRK42903982 | K4: =TRIM(Dataset!K4) -> 8 | L4: =Dataset!L4 -> FREESHIP | M4: =TRIM(Dataset!M4) -> Email | N4: =VALUE(TRIM(Dataset!N4)) -> 2753.4
A5: =TRIM(Dataset!A5) -> ORD200003 | B5: =Dataset!B5 -> 45214 | C5: =TRIM(Dataset!C5) -> C33540 | D5: =TRIM(Dataset!D5) -> Chair | E5: =VALUE(TRIM(Dataset!E5)) -> 1 | F5: =VALUE(TRIM(Dataset!F5)) -> 273.19 | G5: =TRIM(Dataset!G5) -> 275 Main St | H5: =TRIM(Dataset!H5) -> Debit Card | I5: =TRIM(Dataset!I5) -> Returned | J5: =TRIM(Dataset!J5) -> TRK62788070 | K5: =TRIM(Dataset!K5) -> 5 | L5: =Dataset!L5 -> SAVE10 | M5: =TRIM(Dataset!M5) -> Facebook | N5: =VALUE(TRIM(Dataset!N5)) -> 273.19
A6: =TRIM(Dataset!A6) -> ORD200004 | B6: =Dataset!B6 -> 45785 | C6: =TRIM(Dataset!C6) -> C81840 | D6: =TRIM(Dataset!D6) -> Printer | E6: =VALUE(TRIM(Dataset!E6)) -> 4 | F6: =VALUE(TRIM(Dataset!F6)) -> 626.01 | G6: =TRIM(Dataset!G6) -> 668 Main St | H6: =TRIM(Dataset!H6) -> Online | I6: =TRIM(Dataset!I6) -> Delivered | J6: =TRIM(Dataset!J6) -> TRK29241424 | K6: =TRIM(Dataset!K6) -> 8 | L6: =Dataset!L6 -> SAVE10 | M6: =TRIM(Dataset!M6) -> Email | N6: =VALUE(TRIM(Dataset!N6)) -> 2504.04
A7: =TRIM(Dataset!A7) -> ORD200005 | B7: =Dataset!B7 -> 45222 | C7: =TRIM(Dataset!C7) -> C37249 | D7: =TRIM(Dataset!D7) -> Phone | E7: =VALUE(TRIM(Dataset!E7)) -> 2 | F7: =VALUE(TRIM(Dataset!F7)) -> 245.86 | G7: =TRIM(Dataset!G7) -> 934 Main St | H7: =TRIM(Dataset!H7) -> Credit Card | I7: =TRIM(Dataset!I7) -> Shipped | J7: =TRIM(Dataset!J7) -> TRK72976927 | K7: =TRIM(Dataset!K7) -> 4 | L7: =Dataset!L7 -> SAVE10 | M7: =TRIM(Dataset!M7) -> Instagram | N7: =VALUE(TRIM(Dataset!N7)) -> 491.72
A8: =TRIM(Dataset!A8) -> ORD200006 | B8: =Dataset!B8 -> 45825 | C8: =TRIM(Dataset!C8) -> C83492 | D8: =TRIM(Dataset!D8) -> Laptop | E8: =VALUE(TRIM(Dataset!E8)) -> 1 | F8: =VALUE(TRIM(Dataset!F8)) -> 664.42 | G8: =TRIM(Dataset!G8) -> 986 Main St | H8: =TRIM(Dataset!H8) -> Gift Card | I8: =TRIM(Dataset!I8) -> Returned | J8: =TRIM(Dataset!J8) -> TRK96417362 | K8: =TRIM(Dataset!K8) -> 6 | L8: =Dataset!L8 -> SAVE10 | M8: =TRIM(Dataset!M8) -> Facebook | N8: =VALUE(TRIM(Dataset!N8)) -> 664.42
A9: =TRIM(Dataset!A9) -> ORD200007 | B9: =Dataset!B9 -> 45058 | C9: =TRIM(Dataset!C9) -> C41460 | D9: =TRIM(Dataset!D9) -> Monitor | E9: =VALUE(TRIM(Dataset!E9)) -> 5 | F9: =VALUE(TRIM(Dataset!F9)) -> 149.55 | G9: =TRIM(Dataset!G9) -> 706 Main St | H9: =TRIM(Dataset!H9) -> Cash | I9: =TRIM(Dataset!I9) -> Shipped | J9: =TRIM(Dataset!J9) -> TRK78809193 | K9: =TRIM(Dataset!K9) -> 9 | L9: =Dataset!L9 -> FREESHIP | M9: =TRIM(Dataset!M9) -> Facebook | N9: =VALUE(TRIM(Dataset!N9)) -> 747.75
A10: =TRIM(Dataset!A10) -> ORD200008 | B10: =Dataset!B10 -> 45749 | C10: =TRIM(Dataset!C10) -> C26817 | D10: =TRIM(Dataset!D10) -> Phone | E10: =VALUE(TRIM(Dataset!E10)) -> 2 | F10: =VALUE(TRIM(Dataset!F10)) -> 134.28 | G10: =TRIM(Dataset!G10) -> 904 Main St | H10: =TRIM(Dataset!H10) -> Gift Card | I10: =TRIM(Dataset!I10) -> Cancelled | J10: =TRIM(Dataset!J10) -> TRK61042692 | K10: =TRIM(Dataset!K10) -> 2 | L10: NO COUPON | M10: =TRIM(Dataset!M10) -> Email | N10: =VALUE(TRIM(Dataset!N10)) -> 268.56
A11: =TRIM(Dataset!A11) -> ORD200009 | B11: =Dataset!B11 -> 45251 | C11: =TRIM(Dataset!C11) -> C31946 | D11: =TRIM(Dataset!D11) -> Desk | E11: =VALUE(TRIM(Dataset!E11)) -> 4 | F11: =VALUE(TRIM(Dataset!F11)) -> 509.38 | G11: =TRIM(Dataset!G11) -> 102 Main St | H11: =TRIM(Dataset!H11) -> Credit Card | I11: =TRIM(Dataset!I11) -> Shipped | J11: =TRIM(Dataset!J11) -> TRK33478363 | K11: =TRIM(Dataset!K11) -> 6 | L11: =Dataset!L11 -> SAVE10 | M11: =TRIM(Dataset!M11) -> Google | N11: =VALUE(TRIM(Dataset!N11)) -> 2037.52
A12: =TRIM(Dataset!A12) -> ORD200010 | B12: =Dataset!B12 -> 45289 | C12: =TRIM(Dataset!C12) -> C43443 | D12: =TRIM(Dataset!D12) -> Tablet | E12: =VALUE(TRIM(Dataset!E12)) -> 5 | F12: =VALUE(TRIM(Dataset!F12)) -> 625.97 | G12: =TRIM(Dataset!G12) -> 333 Main St | H12: =TRIM(Dataset!H12) -> Credit Card | I12: =TRIM(Dataset!I12) -> Returned | J12: =TRIM(Dataset!J12) -> TRK98859248 | K12: =TRIM(Dataset!K12) -> 9 | L12: =Dataset!L12 -> WINTER15 | M12: =TRIM(Dataset!M12) -> Instagram | N12: =VALUE(TRIM(Dataset!N12)) -> 3129.85
A13: =TRIM(Dataset!A13) -> ORD200011 | B13: =Dataset!B13 -> 45339 | C13: =TRIM(Dataset!C13) -> C93861 | D13: =TRIM(Dataset!D13) -> Monitor | E13: =VALUE(TRIM(Dataset!E13)) -> 3 | F13: =VALUE(TRIM(Dataset!F13)) -> 49.14 | G13: =TRIM(Dataset!G13) -> 831 Main St | H13: =TRIM(Dataset!H13) -> Online | I13: =TRIM(Dataset!I13) -> Returned | J13: =TRIM(Dataset!J13) -> TRK48234646 | K13: =TRIM(Dataset!K13) -> 7 | L13: =Dataset!L13 -> SAVE10 | M13: =TRIM(Dataset!M13) -> Email | N13: =VALUE(TRIM(Dataset!N13)) -> 147.42
A14: =TRIM(Dataset!A14) -> ORD200012 | B14: =Dataset!B14 -> 45580 | C14: =TRIM(Dataset!C14) -> C38785 | D14: =TRIM(Dataset!D14) -> Monitor | E14: =VALUE(TRIM(Dataset!E14)) -> 2 | F14: =VALUE(TRIM(Dataset!F14)) -> 180.5 | G14: =TRIM(Dataset!G14) -> 179 Main St | H14: =TRIM(Dataset!H14) -> Debit Card | I14: =TRIM(Dataset!I14) -> Pending | J14: =TRIM(Dataset!J14) -> TRK20419991 | K14: =TRIM(Dataset!K14) -> 6 | L14: =Dataset!L14 -> FREESHIP | M14: =TRIM(Dataset!M14) -> Referral | N14: =VALUE(TRIM(Dataset!N14)) -> 361
A15: =TRIM(Dataset!A15) -> ORD200013 | B15: =Dataset!B15 -> 45168 | C15: =TRIM(Dataset!C15) -> C88348 | D15: =TRIM(Dataset!D15) -> Laptop | E15: =VALUE(TRIM(Dataset!E15)) -> 3 | F15: =VALUE(TRIM(Dataset!F15)) -> 201.49 | G15: =TRIM(Dataset!G15) -> 903 Main St | H15: =TRIM(Dataset!H15) -> Credit Card | I15: =TRIM(Dataset!I15) -> Returned | J15: =TRIM(Dataset!J15) -> TRK81913874 | K15: =TRIM(Dataset!K15) -> 4 | L15: =Dataset!L15 -> FREESHIP | M15: =TRIM(Dataset!M15) -> Facebook | N15: =VALUE(TRIM(Dataset!N15)) -> 604.47
A16: =TRIM(Dataset!A16) -> ORD200014 | B16: =Dataset!B16 -> 45012 | C16: =TRIM(Dataset!C16) -> C98474 | D16: =TRIM(Dataset!D16) -> Tablet | E16: =VALUE(TRIM(Dataset!E16)) -> 2 | F16: =VALUE(TRIM(Dataset!F16)) -> 393.33 | G16: =TRIM(Dataset!G16) -> 980 Main St | H16: =TRIM(Dataset!H16) -> Debit Card | I16: =TRIM(Dataset!I16) -> Pending | J16: =TRIM(Dataset!J16) -> TRK79186539 | K16: =TRIM(Dataset!K16) -> 3 | L16: =Dataset!L16 -> SAVE10 | M16: =TRIM(Dataset!M16) -> Instagram | N16: =VALUE(TRIM(Dataset!N16)) -> 786.66
A17: =TRIM(Dataset!A17) -> ORD200015 | B17: =Dataset!B17 -> 45124 | C17: =TRIM(Dataset!C17) -> C39416 | D17: =TRIM(Dataset!D17) -> Printer | E17: =VALUE(TRIM(Dataset!E17)) -> 1 | F17: =VALUE(TRIM(Dataset!F17)) -> 473.96 | G17: =TRIM(Dataset!G17) -> 942 Main St | H17: =TRIM(Dataset!H17) -> Cash | I17: =TRIM(Dataset!I17) -> Delivered | J17: =TRIM(Dataset!J17) -> TRK54930938 | K17: =TRIM(Dataset!K17) -> 3 | L17: NO COUPON | M17: =TRIM(Dataset!M17) -> Google | N17: =VALUE(TRIM(Dataset!N17)) -> 473.96
A18: =TRIM(Dataset!A18) -> ORD200016 | B18: =Dataset!B18 -> 44950 | C18: =TRIM(Dataset!C18) -> C28976 | D18: =TRIM(Dataset!D18) -> Printer | E18: =VALUE(TRIM(Dataset!E18)) -> 2 | F18: =VALUE(TRIM(Dataset!F18)) -> 533.81 | G18: =TRIM(Dataset!G18) -> 914 Main St | H18: =TRIM(Dataset!H18) -> Credit Card | I18: =TRIM(Dataset!I18) -> Pending | J18: =TRIM(Dataset!J18) -> TRK13194259 | K18: =TRIM(Dataset!K18) -> 3 | L18: =Dataset!L18 -> FREESHIP | M18: =TRIM(Dataset!M18) -> Email | N18: =VALUE(TRIM(Dataset!N18)) -> 1067.62
A19: =TRIM(Dataset!A19) -> ORD200017 | B19: =Dataset!B19 -> 45353 | C19: =TRIM(Dataset!C19) -> C60672 | D19: =TRIM(Dataset!D19) -> Tablet | E19: =VALUE(TRIM(Dataset!E19)) -> 1 | F19: =VALUE(TRIM(Dataset!F19)) -> 423.4 | G19: =TRIM(Dataset!G19) -> 382 Main St | H19: =TRIM(Dataset!H19) -> Debit Card | I19: =TRIM(Dataset!I19) -> Shipped | J19: =TRIM(Dataset!J19) -> TRK11972116 | K19: =TRIM(Dataset!K19) -> 3 | L19: NO COUPON | M19: =TRIM(Dataset!M19) -> Referral | N19: =VALUE(TRIM(Dataset!N19)) -> 423.4
A20: =TRIM(Dataset!A20) -> ORD200018 | B20: =Dataset!B20 -> 45742 | C20: =TRIM(Dataset!C20) -> C84329 | D20: =TRIM(Dataset!D20) -> Desk | E20: =VALUE(TRIM(Dataset!E20)) -> 1 | F20: =VALUE(TRIM(Dataset!F20)) -> 431.44 | G20: =TRIM(Dataset!G20) -> 891 Main St | H20: =TRIM(Dataset!H20) -> Gift Card | I20: =TRIM(Dataset!I20) -> Pending | J20: =TRIM(Dataset!J20) -> TRK65191045 | K20: =TRIM(Dataset!K20) -> 3 | L20: =Dataset!L20 -> SAVE10 | M20: =TRIM(Dataset!M20) -> Facebook | N20: =VALUE(TRIM(Dataset!N20)) -> 431.44
A21: =TRIM(Dataset!A21) -> ORD200019 | B21: =Dataset!B21 -> 44949 | C21: =TRIM(Dataset!C21) -> C14552 | D21: =TRIM(Dataset!D21) -> Monitor | E21: =VALUE(TRIM(Dataset!E21)) -> 5 | F21: =VALUE(TRIM(Dataset!F21)) -> 224 | G21: =TRIM(Dataset!G21) -> 273 Main St | H21: =TRIM(Dataset!H21) -> Cash | I21: =TRIM(Dataset!I21) -> Returned | J21: =TRIM(Dataset!J21) -> TRK59101365 | K21: =TRIM(Dataset!K21) -> 9 | L21: =Dataset!L21 -> SAVE10 | M21: =TRIM(Dataset!M21) -> Google | N21: =VALUE(TRIM(Dataset!N21)) -> 1120
A22: =TRIM(Dataset!A22) -> ORD200020 | B22: =Dataset!B22 -> 45054 | C22: =TRIM(Dataset!C22) -> C54829 | D22: =TRIM(Dataset!D22) -> Chair | E22: =VALUE(TRIM(Dataset!E22)) -> 5 | F22: =VALUE(TRIM(Dataset!F22)) -> 62.51 | G22: =TRIM(Dataset!G22) -> 587 Main St | H22: =TRIM(Dataset!H22) -> Cash | I22: =TRIM(Dataset!I22) -> Pending | J22: =TRIM(Dataset!J22) -> TRK16718651 | K22: =TRIM(Dataset!K22) -> 9 | L22: =Dataset!L22 -> WINTER15 | M22: =TRIM(Dataset!M22) -> Instagram | N22: =VALUE(TRIM(Dataset!N22)) -> 312.55
A23: =TRIM(Dataset!A23) -> ORD200021 | B23: =Dataset!B23 -> 45613 | C23: =TRIM(Dataset!C23) -> C99023 | D23: =TRIM(Dataset!D23) -> Monitor | E23: =VALUE(TRIM(Dataset!E23)) -> 4 | F23: =VALUE(TRIM(Dataset!F23)) -> 342.95 | G23: =TRIM(Dataset!G23) -> 569 Main St | H23: =TRIM(Dataset!H23) -> Cash | I23: =TRIM(Dataset!I23) -> Delivered | J23: =TRIM(Dataset!J23) -> TRK52646983 | K23: =TRIM(Dataset!K23) -> 6 | L23: NO COUPON | M23: =TRIM(Dataset!M23) -> Google | N23: =VALUE(TRIM(Dataset!N23)) -> 1371.8
A24: =TRIM(Dataset!A24) -> ORD200022 | B24: =Dataset!B24 -> 44955 | C24: =TRIM(Dataset!C24) -> C34416 | D24: =TRIM(Dataset!D24) -> Monitor | E24: =VALUE(TRIM(Dataset!E24)) -> 2 | F24: =VALUE(TRIM(Dataset!F24)) -> 49.62 | G24: =TRIM(Dataset!G24) -> 633 Main St | H24: =TRIM(Dataset!H24) -> Online | I24: =TRIM(Dataset!I24) -> Pending | J24: =TRIM(Dataset!J24) -> TRK75937350 | K24: =TRIM(Dataset!K24) -> 2 | L24: =Dataset!L24 -> SAVE10 | M24: =TRIM(Dataset!M24) -> Google | N24: =VALUE(TRIM(Dataset!N24)) -> 99.24
A25: =TRIM(Dataset!A25) -> ORD200023 | B25: =Dataset!B25 -> 45756 | C25: =TRIM(Dataset!C25) -> C42372 | D25: =TRIM(Dataset!D25) -> Phone | E25: =VALUE(TRIM(Dataset!E25)) -> 4 | F25: =VALUE(TRIM(Dataset!F25)) -> 273.25 | G25: =TRIM(Dataset!G25) -> 755 Main St | H25: =TRIM(Dataset!H25) -> Debit Card | I25: =TRIM(Dataset!I25) -> Cancelled | J25: =TRIM(Dataset!J25) -> TRK36168083 | K25: =TRIM(Dataset!K25) -> 5 | L25: =Dataset!L25 -> FREESHIP | M25: =TRIM(Dataset!M25) -> Referral | N25: =VALUE(TRIM(Dataset!N25)) -> 1093
A26: =TRIM(Dataset!A26) -> ORD200024 | B26: =Dataset!B26 -> 45595 | C26: =TRIM(Dataset!C26) -> C17470 | D26: =TRIM(Dataset!D26) -> Laptop | E26: =VALUE(TRIM(Dataset!E26)) -> 2 | F26: =VALUE(TRIM(Dataset!F26)) -> 230.95 | G26: =TRIM(Dataset!G26) -> 956 Main St | H26: =TRIM(Dataset!H26) -> Online | I26: =TRIM(Dataset!I26) -> Delivered | J26: =TRIM(Dataset!J26) -> TRK28775057 | K26: =TRIM(Dataset!K26) -> 3 | L26: =Dataset!L26 -> WINTER15 | M26: =TRIM(Dataset!M26) -> Referral | N26: =VALUE(TRIM(Dataset!N26)) -> 461.9
A27: =TRIM(Dataset!A27) -> ORD200025 | B27: =Dataset!B27 -> 45497 | C27: =TRIM(Dataset!C27) -> C42577 | D27: =TRIM(Dataset!D27) -> Monitor | E27: =VALUE(TRIM(Dataset!E27)) -> 1 | F27: =VALUE(TRIM(Dataset!F27)) -> 399.98 | G27: =TRIM(Dataset!G27) -> 709 Main St | H27: =TRIM(Dataset!H27) -> Debit Card | I27: =TRIM(Dataset!I27) -> Delivered | J27: =TRIM(Dataset!J27) -> TRK69423327 | K27: =TRIM(Dataset!K27) -> 3 | L27: =Dataset!L27 -> WINTER15 | M27: =TRIM(Dataset!M27) -> Email | N27: =VALUE(TRIM(Dataset!N27)) -> 399.98
A28: =TRIM(Dataset!A28) -> ORD200026 | B28: =Dataset!B28 -> 45357 | C28: =TRIM(Dataset!C28) -> C21944 | D28: =TRIM(Dataset!D28) -> Laptop | E28: =VALUE(TRIM(Dataset!E28)) -> 5 | F28: =VALUE(TRIM(Dataset!F28)) -> 59.55 | G28: =TRIM(Dataset!G28) -> 296 Main St | H28: =TRIM(Dataset!H28) -> Online | I28: =TRIM(Dataset!I28) -> Delivered | J28: =TRIM(Dataset!J28) -> TRK80276812 | K28: =TRIM(Dataset!K28) -> 6 | L28: NO COUPON | M28: =TRIM(Dataset!M28) -> Referral | N28: =VALUE(TRIM(Dataset!N28)) -> 297.75
A29: =TRIM(Dataset!A29) -> ORD200027 | B29: =Dataset!B29 -> 45344 | C29: =TRIM(Dataset!C29) -> C97593 | D29: =TRIM(Dataset!D29) -> Printer | E29: =VALUE(TRIM(Dataset!E29)) -> 1 | F29: =VALUE(TRIM(Dataset!F29)) -> 472.74 | G29: =TRIM(Dataset!G29) -> 881 Main St | H29: =TRIM(Dataset!H29) -> Online | I29: =TRIM(Dataset!I29) -> Shipped | J29: =TRIM(Dataset!J29) -> TRK89117573 | K29: =TRIM(Dataset!K29) -> 6 | L29: =Dataset!L29 -> WINTER15 | M29: =TRIM(Dataset!M29) -> Google | N29: =VALUE(TRIM(Dataset!N29)) -> 472.74
A30: =TRIM(Dataset!A30) -> ORD200028 | B30: =Dataset!B30 -> 45251 | C30: =TRIM(Dataset!C30) -> C59823 | D30: =TRIM(Dataset!D30) -> Phone | E30: =VALUE(TRIM(Dataset!E30)) -> 4 | F30: =VALUE(TRIM(Dataset!F30)) -> 160.07 | G30: =TRIM(Dataset!G30) -> 568 Main St | H30: =TRIM(Dataset!H30) -> Online | I30: =TRIM(Dataset!I30) -> Pending | J30: =TRIM(Dataset!J30) -> TRK65895539 | K30: =TRIM(Dataset!K30) -> 5 | L30: NO COUPON | M30: =TRIM(Dataset!M30) -> Email | N30: =VALUE(TRIM(Dataset!N30)) -> 640.28
A31: =TRIM(Dataset!A31) -> ORD200029 | B31: =Dataset!B31 -> 45555 | C31: =TRIM(Dataset!C31) -> C33260 | D31: =TRIM(Dataset!D31) -> Desk | E31: =VALUE(TRIM(Dataset!E31)) -> 3 | F31: =VALUE(TRIM(Dataset!F31)) -> 423.53 | G31: =TRIM(Dataset!G31) -> 930 Main St | H31: =TRIM(Dataset!H31) -> Credit Card | I31: =TRIM(Dataset!I31) -> Delivered | J31: =TRIM(Dataset!J31) -> TRK59744090 | K31: =TRIM(Dataset!K31) -> 6 | L31: =Dataset!L31 -> SAVE10 | M31: =TRIM(Dataset!M31) -> Referral | N31: =VALUE(TRIM(Dataset!N31)) -> 1270.59
A32: =TRIM(Dataset!A32) -> ORD200030 | B32: =Dataset!B32 -> 45738 | C32: =TRIM(Dataset!C32) -> C44267 | D32: =TRIM(Dataset!D32) -> Monitor | E32: =VALUE(TRIM(Dataset!E32)) -> 2 | F32: =VALUE(TRIM(Dataset!F32)) -> 426.7 | G32: =TRIM(Dataset!G32) -> 895 Main St | H32: =TRIM(Dataset!H32) -> Online | I32: =TRIM(Dataset!I32) -> Pending | J32: =TRIM(Dataset!J32) -> TRK54751444 | K32: =TRIM(Dataset!K32) -> 5 | L32: =Dataset!L32 -> SAVE10 | M32: =TRIM(Dataset!M32) -> Referral | N32: =VALUE(TRIM(Dataset!N32)) -> 853.4
A33: =TRIM(Dataset!A33) -> ORD200031 | B33: =Dataset!B33 -> 45107 | C33: =TRIM(Dataset!C33) -> C26445 | D33: =TRIM(Dataset!D33) -> Chair | E33: =VALUE(TRIM(Dataset!E33)) -> 3 | F33: =VALUE(TRIM(Dataset!F33)) -> 500.08 | G33: =TRIM(Dataset!G33) -> 996 Main St | H33: =TRIM(Dataset!H33) -> Debit Card | I33: =TRIM(Dataset!I33) -> Returned | J33: =TRIM(Dataset!J33) -> TRK31229981 | K33: =TRIM(Dataset!K33) -> 6 | L33: NO COUPON | M33: =TRIM(Dataset!M33) -> Facebook | N33: =VALUE(TRIM(Dataset!N33)) -> 1500.24
A34: =TRIM(Dataset!A34) -> ORD200032 | B34: =Dataset!B34 -> 45047 | C34: =TRIM(Dataset!C34) -> C12388 | D34: =TRIM(Dataset!D34) -> Tablet | E34: =VALUE(TRIM(Dataset!E34)) -> 5 | F34: =VALUE(TRIM(Dataset!F34)) -> 536.72 | G34: =TRIM(Dataset!G34) -> 830 Main St | H34: =TRIM(Dataset!H34) -> Cash | I34: =TRIM(Dataset!I34) -> Delivered | J34: =TRIM(Dataset!J34) -> TRK99261395 | K34: =TRIM(Dataset!K34) -> 10 | L34: NO COUPON | M34: =TRIM(Dataset!M34) -> Email | N34: =VALUE(TRIM(Dataset!N34)) -> 2683.6
A35: =TRIM(Dataset!A35) -> ORD200033 | B35: =Dataset!B35 -> 45082 | C35: =TRIM(Dataset!C35) -> C52184 | D35: =TRIM(Dataset!D35) -> Chair | E35: =VALUE(TRIM(Dataset!E35)) -> 1 | F35: =VALUE(TRIM(Dataset!F35)) -> 162.77 | G35: =TRIM(Dataset!G35) -> 912 Main St | H35: =TRIM(Dataset!H35) -> Online | I35: =TRIM(Dataset!I35) -> Cancelled | J35: =TRIM(Dataset!J35) -> TRK73312471 | K35: =TRIM(Dataset!K35) -> 4 | L35: =Dataset!L35 -> WINTER15 | M35: =TRIM(Dataset!M35) -> Facebook | N35: =VALUE(TRIM(Dataset!N35)) -> 162.77
A36: =TRIM(Dataset!A36) -> ORD200034 | B36: =Dataset!B36 -> 44933 | C36: =TRIM(Dataset!C36) -> C67195 | D36: =TRIM(Dataset!D36) -> Chair | E36: =VALUE(TRIM(Dataset!E36)) -> 4 | F36: =VALUE(TRIM(Dataset!F36)) -> 576.52 | G36: =TRIM(Dataset!G36) -> 926 Main St | H36: =TRIM(Dataset!H36) -> Credit Card | I36: =TRIM(Dataset!I36) -> Pending | J36: =TRIM(Dataset!J36) -> TRK55467915 | K36: =TRIM(Dataset!K36) -> 5 | L36: =Dataset!L36 -> WINTER15 | M36: =TRIM(Dataset!M36) -> Facebook | N36: =VALUE(TRIM(Dataset!N36)) -> 2306.08
A37: =TRIM(Dataset!A37) -> ORD200035 | B37: =Dataset!B37 -> 45633 | C37: =TRIM(Dataset!C37) -> C50304 | D37: =TRIM(Dataset!D37) -> Monitor | E37: =VALUE(TRIM(Dataset!E37)) -> 2 | F37: =VALUE(TRIM(Dataset!F37)) -> 465.15 | G37: =TRIM(Dataset!G37) -> 128 Main St | H37: =TRIM(Dataset!H37) -> Online | I37: =TRIM(Dataset!I37) -> Shipped | J37: =TRIM(Dataset!J37) -> TRK46850888 | K37: =TRIM(Dataset!K37) -> 2 | L37: =Dataset!L37 -> SAVE10 | M37: =TRIM(Dataset!M37) -> Facebook | N37: =VALUE(TRIM(Dataset!N37)) -> 930.3
A38: =TRIM(Dataset!A38) -> ORD200036 | B38: =Dataset!B38 -> 45785 | C38: =TRIM(Dataset!C38) -> C59337 | D38: =TRIM(Dataset!D38) -> Laptop | E38: =VALUE(TRIM(Dataset!E38)) -> 2 | F38: =VALUE(TRIM(Dataset!F38)) -> 534.43 | G38: =TRIM(Dataset!G38) -> 465 Main St | H38: =TRIM(Dataset!H38) -> Debit Card | I38: =TRIM(Dataset!I38) -> Pending | J38: =TRIM(Dataset!J38) -> TRK50961250 | K38: =TRIM(Dataset!K38) -> 5 | L38: NO COUPON | M38: =TRIM(Dataset!M38) -> Facebook | N38: =VALUE(TRIM(Dataset!N38)) -> 1068.86
A39: =TRIM(Dataset!A39) -> ORD200037 | B39: =Dataset!B39 -> 45579 | C39: =TRIM(Dataset!C39) -> C10054 | D39: =TRIM(Dataset!D39) -> Laptop | E39: =VALUE(TRIM(Dataset!E39)) -> 2 | F39: =VALUE(TRIM(Dataset!F39)) -> 76.74 | G39: =TRIM(Dataset!G39) -> 409 Main St | H39: =TRIM(Dataset!H39) -> Cash | I39: =TRIM(Dataset!I39) -> Returned | J39: =TRIM(Dataset!J39) -> TRK94005261 | K39: =TRIM(Dataset!K39) -> 7 | L39: =Dataset!L39 -> SAVE10 | M39: =TRIM(Dataset!M39) -> Instagram | N39: =VALUE(TRIM(Dataset!N39)) -> 153.48
A40: =TRIM(Dataset!A40) -> ORD200038 | B40: =Dataset!B40 -> 45645 | C40: =TRIM(Dataset!C40) -> C15924 | D40: =TRIM(Dataset!D40) -> Laptop | E40: =VALUE(TRIM(Dataset!E40)) -> 1 | F40: =VALUE(TRIM(Dataset!F40)) -> 245.89 | G40: =TRIM(Dataset!G40) -> 549 Main St | H40: =TRIM(Dataset!H40) -> Debit Card | I40: =TRIM(Dataset!I40) -> Delivered | J40: =TRIM(Dataset!J40) -> TRK14835975 | K40: =TRIM(Dataset!K40) -> 3 | L40: =Dataset!L40 -> SAVE10 | M40: =TRIM(Dataset!M40) -> Google | N40: =VALUE(TRIM(Dataset!N40)) -> 245.89
...

Sheet Analysis
A1: Most Selling Product | D1: Revenue by Product | G1: Most Frequent Orderstatus | J1: Average Items per cart
A2: Product | B2: Sum of Quantity | D2: Product | E2: Sum of TotalPrice | G2: OrderStatus | H2: Total Orders | J2: Product | K2: Average of Quantity
A3: Phone | B3: 411 | D3: Chair | E3: 195620.11 | G3: Delivered | H3: 231 | J3: Chair | K3: 3.1573034
A4: Monitor | B4: 480 | D4: Printer | E4: 195612.61 | G4: Shipped | H4: 235 | J4: Desk | K4: 2.9882353
A5: Tablet | B5: 497 | D5: Laptop | E5: 192126.56 | G5: Pending | H5: 237 | J5: Laptop | K5: 3.0924855
A6: Desk | B6: 508 | D6: Tablet | E6: 186568.95 | G6: Returned | H6: 247 | J6: Monitor | K6: 2.9447853
A7: Laptop | B7: 535 | D7: Monitor | E7: 175651.41 | G7: Cancelled | H7: 250 | J7: Phone | K7: 2.6346154
A8: Printer | B8: 542 | D8: Desk | E8: 167459.93 | G8: Grand Total | H8: 1200 | J8: Printer | K8: 2.9944751
A9: Chair | B9: 562 | D9: Phone | E9: 151722.39 | J9: Tablet | K9: 2.7765363
A10: Grand Total | B10: 3535 | D10: Grand Total | E10: 1264762 | J10: Grand Total | K10: 2.9458333
A12: Most used payment Method | D12: Top Referral Source | G12: Sales Overtime | J12: Top Referral Source
A13: Payment Method | B13: Total Orders | D13: CouponCode | E13: Total Orders | G13: CouponCode | H13: Sum of Quantity | I13: Sum of TotalPrice | J13: CouponCode | K13: Total Orders
A14: Gift Card | B14: 230 | D14: FREESHIP | E14: 313 | G14: 2023 | H14: 1524 | I14: 552643.24 | J14: FREESHIP | K14: 0.26083333
A15: Debit Card | B15: 232 | D15: NO COUPON | E15: 309 | G15: 2024 | H15: 1351 | I15: 480235.87 | J15: NO COUPON | K15: 0.2575
A16: Credit Card | B16: 234 | D16: WINTER15 | E16: 292 | G16: 2025 | H16: 660 | I16: 231882.85 | J16: WINTER15 | K16: 0.24333333
A17: Cash | B17: 246 | D17: SAVE10 | E17: 286 | G17: Grand Total | H17: 3535 | I17: 1264762 | J17: SAVE10 | K17: 0.23833333
A18: Online | B18: 258 | D18: Grand Total | E18: 1200 | J18: Grand Total | K18: 1
A19: Grand Total | B19: 1200
A21: Revenue | B21: Quantity | D21: Average of TotalPrice
A22: 1264762 | B22: 3535 | D22: 1053.9683

Sheet Dashboard

Sheet Outliner 
A2: Order with unsual high price | D2: Product with unsual high price | G2: Orders with Unsual quantity
A3: OrderID | B3: Cost of orders | D3: Product | E3: Average of UnitPrice | G3: OrderID | H3: Sum of Quantity
A4: ORD200789 | B4: 3456.4 | D4: Phone | E4: 375.21756 | G4: ORD201051 | H4: 5
A5: ORD201122 | B5: 3390.95 | D5: Tablet | E5: 367.67911 | G5: ORD201006 | H5: 5
A6: ORD200632 | B6: 3390.8 | D6: Monitor | E6: 358.66362 | G6: ORD201100 | H6: 5
A7: ORD200469 | B7: 3384.9 | D7: Laptop | E7: 357.70705 | G7: ORD200907 | H7: 5
A8: ORD200328 | B8: 3370.2 | D8: Chair | E8: 355.66028 | G8: ORD201031 | H8: 5
A9: ORD200107 | B9: 3353.75 | D9: Printer | E9: 351.71492 | G9: ORD200911 | H9: 5
A10: ORD200326 | B10: 3352.4 | D10: Desk | E10: 329.60812 | G10: ORD201079 | H10: 5
A11: ORD201065 | B11: 3334 | D11: Grand Total | E11: 356.41275 | G11: ORD200913 | H11: 5
A12: ORD201031 | B12: 3322.55 | G12: ORD201146 | H12: 5
A13: ORD200463 | B13: 3313.9 | G13: ORD200916 | H13: 5
A14: ORD200361 | B14: 3299.25 | G14: ORD201016 | H14: 5
A15: ORD200367 | B15: 3293.85 | G15: ORD200917 | H15: 5
A16: ORD200837 | B16: 3277.75 | G16: ORD200900 | H16: 5
A17: ORD200527 | B17: 3267.35 | G17: ORD200918 | H17: 5
A18: ORD200768 | B18: 3267.3 | G18: ORD201062 | H18: 5
A19: ORD200889 | B19: 3253.6 | G19: ORD200924 | H19: 5
A20: ORD200540 | B20: 3243.25 | G20: ORD201092 | H20: 5
A21: ORD200802 | B21: 3223.2 | G21: ORD200925 | H21: 5
A22: ORD200957 | B22: 3219.45 | G22: ORD201126 | H22: 5
A23: ORD200086 | B23: 3215.15 | G23: ORD200941 | H23: 5
... A1204: Grand Total | B1204: 1264762 | G1204: Grand Total | H1204: 3535
